Workbook

Sheet March 22 - RCH 301
A1: Time | B1: Name | C1: Role | D1: Count | F1: Time | G1: Name | H1: Role | I1: Count | K1: Time | L1: Name | M1: Role | N1: Count
A2: Sum | D2: =sum(D3:D82) -> 68 | I2: =sum(I3:I82) -> 66 | N2: =sum(N3:N82) -> 52
A3: 9:00am - 1:00pm | B3: Aarushi Awasthi | C3: Receptionist | D3: =counta(B3:B4) -> 2 | E3: x | F3: 1:00pm - 5:00pm | G3: Kate Korsch | H3: Receptionist | I3: =counta(G3:G5) -> 2 | K3: 5:00pm - 9:00pm | L3: Aarushi Awasthi | M3: Receptionist | N3: =counta(L3:L5) -> 1
A4: 9:00am - 1:00pm | B4: Bon Lim | C4: Receptionist | E4: x | F4: 1:00pm - 5:00pm | G4: Qin Du | H4: Receptionist/Mentor
A9: 9:00am - 1:00pm | B9: Eric | C9: Tax Boss | D9: =counta(B9:B15) -> 7 | E9: x | F9: 1:00pm - 5:00pm | G9: Eric | H9: Tax Boss | I9: =counta(G9:G15) -> 7 | K9: 5:00pm - 9:00pm | L9: Eric | M9: Tax Boss | N9: =counta(L9:L15) -> 7
A10: 9:00am - 1:00pm | B10: Rebecca | C10: Tax Guru | E10: x | F10: 1:00pm - 5:00pm | G10: Rebecca | H10: Tax Guru | K10: 5:00pm - 9:00pm | L10: Rebecca | M10: Tax Guru
A11: 9:00am - 1:00pm | B11: Baldwyn Tai | C11: Tax Guru's Minion | E11: x | F11: 1:00pm - 5:00pm | G11: Baldwyn Tai | H11: Tax Guru's Minion | K11: 5:00pm - 9:00pm | L11: Baldwyn Tai | M11: Tax Guru's Minion
A12: 9:00am - 1:00pm | B12: Ben | C12: Unemployed Tax Grunt | E12: x | F12: 1:00pm - 5:00pm | G12: Ben | H12: Unemployed Tax Grunt | K12: 5:00pm - 9:00pm | L12: Ben | M12: Unemployed Tax Grunt
A13: 9:00am - 1:00pm | B13: Krisha Shah | C13: IS | E13: x | F13: 1:00pm - 5:00pm | G13: Krisha Shah | H13: IS | K13: 5:00pm - 9:00pm | L13: Krisha Shah | M13: IS
A14: 9:00am - 1:00pm | B14: Kabilash | C14: IS | E14: x | F14: 1:00pm - 5:00pm | G14: Kabilash | H14: IS | K14: 5:00pm - 9:00pm | L14: Kabilash | M14: IS
A15: 9:00am - 1:00pm | B15: Aaron Gao | C15: IS | E15: x | G15: Aaron Gao | H15: IS | K15: 5:00pm - 9:00pm | L15: Aaron Gao | M15: IS
A17: 9:00am - 1:00pm | B17: Amy Cheung | C17: Mentor | D17: =counta(B17:B36) -> 20 | E17: x | F17: 1:00pm - 5:00pm | G17: Amy Cheung | H17: Mentor | I17: =counta(G17:G36) -> 19 | J17: x | K17: 5:00pm - 9:00pm | L17: Andrew Pang | M17: Mentor/Flex | N17: =counta(L17:L36) -> 17
A18: 9:00am - 1:00pm | B18: Andrew Pang | C18: Mentor/Flex | E18: x | F18: 1:00pm - 5:00pm | G18: Andrew Pang | H18: Mentor/Flex | J18: x | K18: 5:00pm - 9:00pm | L18: Anna Zhong | M18: Mentor
A19: 9:00am - 1:00pm | B19: Audrey Lee | C19: Mentor | E19: x | F19: 1:00pm - 5:00pm | G19: Audrey Lee | H19: Mentor/Flex | J19: x | K19: 5:00pm - 9:00pm | L19: Audrey Lee | M19: Mentor/Flex
A20: 9:00am - 1:00pm | B20: Aurora Wang | C20: Mentor | E20: x | F20: 1:00pm - 5:00pm | G20: Aurora Wang | H20: Mentor | J20: x | K20: 5:00pm - 9:00pm | L20: Aurora Wang | M20: Mentor
A21: 9:00am - 1:00pm | B21: Christina Nie | C21: Mentor | E21: x | F21: 1:00pm - 5:00pm | G21: Christina Nie | H21: Mentor | J21: x | K21: 5:00pm - 9:00pm | L21: Christina Nie | M21: Mentor
A22: 9:00am - 1:00pm | B22: Jadon Xu | C22: Mentor | E22: x | F22: 1:00pm - 5:00pm | K22: 5:00pm - 9:00pm | L22: Kevin Pham | M22: Mentor/Flex
A23: 9:00am - 1:00pm | B23: Kevin Pham | C23: Mentor/Flex | E23: x | F23: 1:00pm - 5:00pm | G23: Jadon Xu | H23: Mentor | J23: x | K23: 5:00pm - 9:00pm | L23: Lillian Chen | M23: Mentor
A24: 9:00am - 1:00pm | B24: Lillian Chen | C24: Mentor | E24: x | F24: 1:00pm - 5:00pm | G24: Manisha Royal | H24: Mentor | J24: x | K24: 5:00pm - 9:00pm | L24: Mingrui Xu | M24: Mentor
A25: 9:00am - 1:00pm | B25: Melissa Guo | C25: Mentor | E25: x | F25: 1:00pm - 5:00pm | G25: Melissa Guo | H25: Mentor | J25: x | K25: 5:00pm - 9:00pm | L25: Qin Du | M25: Mentor
A26: 9:00am - 1:00pm | B26: Nikola Simonovic | C26: Mentor | E26: x | F26: 1:00pm - 5:00pm | G26: Mingrui Xu | H26: Mentor | J26: x | K26: 5:00pm - 9:00pm | L26: Steven Ye | M26: Mentor
A27: 9:00am - 1:00pm | B27: Prabjot Passi | C27: Mentor | E27: x | F27: 1:00pm - 5:00pm | G27: Nikola Simonovic | H27: Mentor | J27: x | K27: 5:00pm - 9:00pm | L27: tiffany chen | M27: Mentor
A28: 9:00am - 1:00pm | B28: Qin Du | C28: Mentor | E28: x | F28: 1:00pm - 5:00pm | G28: Prabjot Passi | H28: Mentor | K28: 5:00pm - 9:00pm | L28: Timothy Chen | M28: Mentor
A29: 9:00am - 1:00pm | B29: Scarlett Xia | C29: Mentor | E29: x | F29: 1:00pm - 5:00pm | G29: Scarlett Xia | H29: Mentor | J29: x | K29: 5:00pm - 9:00pm | L29: Victoria He | M29: Mentor
A30: 9:00am - 1:00pm | B30: Seniru De Silva | C30: Mentor | E30: x | F30: 1:00pm - 5:00pm | G30: Seniru De Silva | H30: Mentor | K30: 5:00pm - 9:00pm | L30: Vivian Zhong | M30: Mentor
A31: 9:00am - 1:00pm | B31: Steven Ye | C31: Mentor | E31: x | F31: 1:00pm - 5:00pm | G31: Steven Ye | H31: Mentor | J31: x | K31: 5:00pm - 9:00pm | L31: Yizhen Chen | M31: Mentor/Flex
A32: 9:00am - 1:00pm | B32: tiffany chen | C32: Mentor | E32: x | F32: 1:00pm - 5:00pm | G32: tiffany chen | H32: Mentor | J32: x | K32: 5:00pm - 9:00pm | L32: Yuqi Wang | M32: Mentor
A33: 9:00am - 1:00pm | B33: Timothy Chen | C33: Mentor | E33: x | F33: 1:00pm - 5:00pm | G33: Timothy Chen | H33: Mentor | J33: x | K33: 5:00pm - 9:00pm | L33: Zhiyue Huang | M33: Mentor
A34: 9:00am - 1:00pm | B34: Vivian Lu | C34: Mentor | E34: x | F34: 1:00pm - 5:00pm | G34: Victoria He | H34: Mentor | J34: x
A35: 9:00am - 1:00pm | B35: Yizhen Chen | C35: Mentor/Flex | E35: x | F35: 1:00pm - 5:00pm | G35: Yizhen Chen | H35: Mentor/Flex | J35: x
A36: 9:00am - 1:00pm | B36: Yutong Xu | C36: Mentor | E36: x | F36: 1:00pm - 5:00pm | G36: Yutong Xu | H36: Mentor | J36: x
A37: =A36 -> 9:00am - 1:00pm | B37: Harper Zhang | C37: Mentor | E37: x | F37: =F36 -> 1:00pm - 5:00pm | G37: Melody Yu | H37: Mentor | J37: x
A38: =A37 -> 9:00am - 1:00pm | B38: Melody Yu | C38: Mentor | E38: x | F38: 9:00am - 1:00pm | G38: Kevin Pham | H38: Mentor/Flex | J38: x
A40: 9:00am - 1:00pm | B40: Aghchaya Satheskishan | C40: Tax Filer | D40: =counta(B40:B94) -> 39 | E40: x | F40: 1:00pm - 5:00pm | G40: Aghchaya Satheskishan | H40: Tax Filer | I40: =counta(G40:G94) -> 38 | K40: 5:00pm - 9:00pm | L40: Abisha Vigneswaran | M40: Tax Filer | N40: =counta(L40:L94) -> 27
A41: 9:00am - 1:00pm | B41: Aneil Ghosh | C41: Tax Filer | E41: x | F41: 1:00pm - 5:00pm | G41: Alex Hu | H41: Tax Filer
A42: 9:00am - 1:00pm | B42: Arthy Mathan | C42: Tax Filer | E42: x | F42: 1:00pm - 5:00pm | G42: Aneil Ghosh | H42: Tax Filer | K42: 5:00pm - 9:00pm | L42: Andrew Zulawski-Dayeh | M42: Tax Filer
A43: 9:00am - 1:00pm | B43: Asjal Khan | C43: Tax Filer | E43: x | F43: 1:00pm - 5:00pm | H43: Tax Filer | K43: 5:00pm - 9:00pm | L43: Aneil Ghosh | M43: Tax Filer
A44: 9:00am - 1:00pm | B44: Brandon Zeng | C44: Tax Filer | E44: x | F44: 1:00pm - 5:00pm | G44: Asjal Khan | H44: Tax Filer | K44: 5:00pm - 9:00pm | M44: Tax Filer
A45: 9:00am - 1:00pm | B45: Campbell Steffler | C45: Tax Filer | E45: x | F45: 1:00pm - 5:00pm | G45: Bhooma Chavadia | H45: Tax Filer | K45: 5:00pm - 9:00pm | L45: Asjal Khan | M45: Tax Filer
A46: 9:00am - 1:00pm | B46: Daniel Solomon | C46: Tax Filer | E46: x | F46: 1:00pm - 5:00pm | G46: Brandon Zeng | H46: Tax Filer | J46: x | K46: 5:00pm - 9:00pm | L46: Brandon Zeng | M46: Tax Filer
...

Sheet March 23 - M3 1006
A1: Time | B1: Name | C1: Role | D1: Count | F1: Time | G1: Name | H1: Role | I1: Count | K1: Time | L1: Name | M1: Role | N1: Count
A2: Sum | D2: =sum(D3:D92) -> 67 | I2: =sum(I3:I92) -> 76 | N2: =sum(N3:N92) -> 59
A3: 9:00am - 1:00pm | B3: Aarushi Awasthi | C3: Receptionist | D3: =counta(B3:B5) -> 2 | E3: x | F3: 1:00pm - 5:00pm | G3: Tiffany Ho | H3: Receptionist | I3: =counta(G3:G5) -> 2 | K3: 5:00pm - 9:00pm | L3: Kate Korsch | M3: Receptionist/Flex | N3: =counta(L3:L5) -> 1
A4: 9:00am - 1:00pm | B4: Bon Lim | C4: Receptionist | E4: x | F4: 1:00pm - 5:00pm | G4: Aarushi Awasthi | H4: Receptionist
A9: 9:00am - 1:00pm | B9: Eric | C9: Tax Boss | D9: =counta(B9:B16) -> 8 | E9: x | F9: 1:00pm - 5:00pm | G9: Eric | H9: Tax Boss | I9: =counta(G9:G16) -> 8 | K9: 5:00pm - 9:00pm | L9: Eric | M9: Tax Boss | N9: =counta(L9:L16) -> 8
A10: 9:00am - 1:00pm | B10: Rebecca | C10: Tax Guru | E10: x | F10: 1:00pm - 5:00pm | G10: Rebecca | H10: Tax Guru | K10: 5:00pm - 9:00pm | L10: Rebecca | M10: Tax Guru
A11: 9:00am - 1:00pm | B11: Baldwyn Tai | C11: Tax Guru's Minion | E11: x | F11: 1:00pm - 5:00pm | G11: Baldwyn Tai | H11: Tax Guru's Minion | K11: 5:00pm - 9:00pm | L11: Baldwyn Tai | M11: Tax Guru's Minion
A12: 9:00am - 1:00pm | B12: Ben | C12: Unemployed Tax Grunt | E12: x | F12: 1:00pm - 5:00pm | G12: Ben | H12: Unemployed Tax Grunt | K12: 5:00pm - 9:00pm | L12: Ben | M12: Unemployed Tax Grunt
A13: 9:00am - 1:00pm | B13: Krisha Shah | C13: IS | E13: x | F13: 1:00pm - 5:00pm | G13: Krisha Shah | H13: IS | K13: 5:00pm - 9:00pm | L13: Krisha Shah | M13: IS
A14: 9:00am - 1:00pm | B14: Kabilash | C14: IS | E14: x | F14: 1:00pm - 5:00pm | G14: Kabilash | H14: IS | K14: 5:00pm - 9:00pm | L14: Kabilash | M14: IS
A15: 9:00am - 1:00pm | B15: Aaron Gao | C15: IS | F15: 1:00pm - 5:00pm | G15: Aaron Gao | H15: IS | K15: 5:00pm - 9:00pm | L15: Aaron Gao | M15: IS
A16: 9:00am - 1:00pm | B16: Hanna Leung | C16: IS | F16: 1:00pm - 5:00pm | G16: Hanna Leung | H16: IS | K16: 5:00pm - 9:00pm | L16: Hanna Leung | M16: IS
A18: 9:00am - 1:00pm | B18: Aimée Boulay | C18: Mentor | D18: =counta(B18:B37) -> 20 | E18: x | F18: 1:00pm - 5:00pm | G18: Aimée Boulay | H18: Mentor | I18: =counta(G18:G37) -> 20 | K18: 5:00pm - 9:00pm | L18: Ambrose Karklins | M18: Mentor | N18: =counta(L18:L37) -> 17
A19: 9:00am - 1:00pm | B19: Ambrose Karklins | C19: Mentor | F19: 1:00pm - 5:00pm | G19: Ambrose Karklins | H19: Mentor | K19: 5:00pm - 9:00pm | L19: Anastasija Kovacevic | M19: Mentor
A20: 9:00am - 1:00pm | B20: Anastasija Kovacevic | C20: Mentor | E20: x | F20: 1:00pm - 5:00pm | G20: Anastasija Kovacevic | H20: Mentor | J20: x | K20: 5:00pm - 9:00pm | L20: Andrew Pang | M20: Mentor/Flex
A21: 9:00am - 1:00pm | B21: Andrew Pang | C21: Mentor/Flex | E21: x | F21: 1:00pm - 5:00pm | G21: Andrew Pang | H21: Mentor/Flex | K21: 5:00pm - 9:00pm | L21: Audrey Lee | M21: Mentor/Flex
A22: 9:00am - 1:00pm | B22: Audrey Lee | C22: Mentor | E22: x | F22: 1:00pm - 5:00pm | G22: Audrey Lee | H22: Mentor/Flex | K22: 5:00pm - 9:00pm | L22: Aurora Wang | M22: Mentor
A23: 9:00am - 1:00pm | B23: Aurora Wang | C23: Mentor | E23: x | F23: 1:00pm - 5:00pm | G23: Aurora Wang | H23: Mentor | K23: 5:00pm - 9:00pm | L23: Claire Kennedy | M23: Mentor
A24: 9:00am - 1:00pm | B24: Christina Nie | C24: Mentor | E24: 0.39001345 | F24: 1:00pm - 5:00pm | G24: Christina Nie | H24: Mentor | K24: 5:00pm - 9:00pm | L24: Enoch Tin | M24: Mentor
A25: 9:00am - 1:00pm | B25: Clement Huang | C25: Mentor | F25: 1:00pm - 5:00pm | G25: Claire Kennedy | H25: Mentor | K25: 5:00pm - 9:00pm | L25: Jake Li | M25: Mentor
A26: 9:00am - 1:00pm | B26: Heer Patel | C26: Mentor | F26: 1:00pm - 5:00pm | G26: Clement Huang | H26: Mentor | K26: 5:00pm - 9:00pm | L26: Julian Worobiec | M26: Mentor
A27: 9:00am - 1:00pm | B27: Jadon Xu | C27: Mentor | E27: x | F27: 1:00pm - 5:00pm | G27: Enoch Tin | H27: Mentor | K27: 5:00pm - 9:00pm | L27: Kevin Pham | M27: Mentor/Flex
A28: 9:00am - 1:00pm | B28: Julian Worobiec | C28: Mentor | F28: 1:00pm - 5:00pm | G28: Heer Patel | H28: Mentor | K28: 5:00pm - 9:00pm | L28: Lillian Chen | M28: Mentor
A29: 9:00am - 1:00pm | B29: Kevin Pham | C29: Mentor/Flex | F29: 1:00pm - 5:00pm | G29: Jadon Xu | H29: Mentor | K29: 5:00pm - 9:00pm | L29: Meghan Tran | M29: Mentor
A30: 9:00am - 1:00pm | B30: Lillian Chen | C30: Mentor | F30: 1:00pm - 5:00pm | G30: Jake Li | H30: Mentor | K30: 5:00pm - 9:00pm | L30: Ryan Hui | M30: Mentor
A31: 9:00am - 1:00pm | B31: Maurice Lam | C31: Mentor | E31: x | F31: 1:00pm - 5:00pm | G31: Julian Worobiec | H31: Mentor | K31: 5:00pm - 9:00pm | L31: Shahana Prabagaran | M31: Mentor
A32: 9:00am - 1:00pm | B32: Muhammad Wasif | C32: Mentor | F32: 1:00pm - 5:00pm | G32: Maurice Lam | H32: Mentor | K32: 5:00pm - 9:00pm | L32: Shrey Patel | M32: Mentor
A33: 9:00am - 1:00pm | B33: Qin Du | C33: Mentor | F33: 1:00pm - 5:00pm | G33: Muhammad Wasif | H33: Mentor | K33: 5:00pm - 9:00pm | L33: Yizhen Chen | M33: Mentor/Flex
A34: 9:00am - 1:00pm | B34: Shahana Prabagaran | C34: Mentor | E34: x | F34: 1:00pm - 5:00pm | G34: Kevin Pham | H34: Mentor/Flex | K34: 5:00pm - 9:00pm | L34: Shane Balkaran | M34: Mentor
A35: 9:00am - 1:00pm | B35: Shane Balkaran | C35: Mentor | E35: x | F35: 1:00pm - 5:00pm | G35: Saniya Nag | H35: Mentor
A36: 9:00am - 1:00pm | B36: Yizhen Chen | C36: Mentor/Flex | E36: x | F36: 1:00pm - 5:00pm | G36: Shahana Prabagaran | H36: Mentor
B37: Melody Yu | C37: =C35 -> Mentor | E37: x | F37: 1:00pm - 5:00pm | G37: Yizhen Chen | H37: Mentor/Flex
A40: 9:00am - 1:00pm | B40: Aghchaya Satheskishan | C40: Tax Filer | D40: =counta(B40:B105) -> 37 | E40: x | F40: 1:00pm - 5:00pm | G40: Alex Hu | H40: Tax Filer | I40: =counta(G40:G105) -> 46 | N40: =counta(L40:L105) -> 33
A41: 9:00am - 1:00pm | B41: Aneil Ghosh | C41: Tax Filer | F41: 1:00pm - 5:00pm | G41: Aneil Ghosh | H41: Tax Filer | K41: 5:00pm - 9:00pm | L41: Alex Hu | M41: Tax Filer
A42: 9:00am - 1:00pm | B42: Anushiya Sathiyamoorthy | C42: Tax Filer | E42: x | F42: 1:00pm - 5:00pm | G42: Annie Chen | H42: Tax Filer | K42: 5:00pm - 9:00pm | L42: Andy Nguyen | M42: Tax Filer
A43: 9:00am - 1:00pm | B43: Arthy Mathan | C43: Tax Filer | F43: 1:00pm - 5:00pm | G43: Anthony Quach | H43: Tax Filer | K43: 5:00pm - 9:00pm | L43: Annie Chen | M43: Tax Filer
A44: 9:00am - 1:00pm | B44: Brandon Phan | C44: Tax Filer | E44: x | F44: 1:00pm - 5:00pm | G44: Anushiya Sathiyamoorthy | H44: Tax Filer | K44: 5:00pm - 9:00pm | L44: Anthony Quach | M44: Tax Filer
A45: 9:00am - 1:00pm | B45: Brendan Tan | C45: Tax Filer | E45: x | F45: 1:00pm - 5:00pm | G45: Bhooma Chavadia | H45: Tax Filer | K45: 5:00pm - 9:00pm | L45: Anushiya Sathiyamoorthy | M45: Tax Filer
A46: 9:00am - 1:00pm | B46: Campbell Steffler | C46: Tax Filer | E46: x | F46: 1:00pm - 5:00pm | G46: Brandon Phan | H46: Tax Filer | K46: 5:00pm - 9:00pm | L46: Brendan Tan | M46: Tax Filer
A47: 9:00am - 1:00pm | B47: Carrie Chung | C47: Tax Filer | E47: x | F47: 1:00pm - 5:00pm | G47: Carrie Chung | H47: Tax Filer | K47: 5:00pm - 9:00pm | L47: Brume Erivwo | M47: Tax Filer
...

Sheet March 29 - M3 1006
A1: Time | B1: Name | C1: Role | D1: Count | F1: Time | G1: First Name | H1: Role | I1: Count | K1: Time | L1: First Name | M1: Role | N1: Count
A2: Sum | D2: =sum(D3:D91) -> 70 | I2: =sum(I3:I91) -> 81 | N2: =sum(N3:N91) -> 52
A3: 9:00am - 1:00pm | B3: Aarushi Awasthi | C3: Receptionist | D3: =counta(B3:B5) -> 3 | F3: 1:00pm - 5:00pm | G3: Kate Korsch | H3: Receptionist/Flex | I3: =counta(G3:G5) -> 3 | K3: 5:00pm - 9:00pm | L3: Kate Korsch | M3: Receptionist/Flex | N3: =counta(L3:L5) -> 1
A4: 9:00am - 1:00pm | B4: Tiffany Ho | C4: Receptionist | F4: 1:00pm - 5:00pm | G4: Qin Du | H4: Receptionist/Mentor
A5: 9:00am - 1:00pm | B5: Bon Lim | C5: Receptionist | F5: 1:00pm - 5:00pm | G5: John Yung | H5: Receptionist/Mentor
F6: 1:00pm - 5:00pm | G6: Quinn Broadhurst | H6: Receptionist
A8: 9:00am - 1:00pm | B8: Eric | C8: Tax Boss | D8: =counta(B8:B14) -> 7 | F8: 1:00pm - 5:00pm | G8: Eric | H8: Tax Boss | I8: =counta(G8:G14) -> 7 | K8: 5:00pm - 9:00pm | L8: Eric | M8: Tax Boss | N8: =counta(L8:L14) -> 7
A9: 9:00am - 1:00pm | B9: Rebecca | C9: Tax Guru | F9: 1:00pm - 5:00pm | G9: Rebecca | H9: Tax Guru | K9: 5:00pm - 9:00pm | L9: Rebecca | M9: Tax Guru
A10: 9:00am - 1:00pm | B10: Baldwyn Tai | C10: Tax Guru's Minion | F10: 1:00pm - 5:00pm | G10: Baldwyn Tai | H10: Tax Guru's Minion | K10: 5:00pm - 9:00pm | L10: Baldwyn Tai | M10: Tax Guru's Minion
A11: 9:00am - 1:00pm | B11: Ben | C11: Unemployed Tax Grunt | F11: 1:00pm - 5:00pm | G11: Ben | H11: Unemployed Tax Grunt | K11: 5:00pm - 9:00pm | L11: Ben | M11: Unemployed Tax Grunt
A12: 9:00am - 1:00pm | B12: Krisha Shah | C12: IS | F12: 1:00pm - 5:00pm | G12: Krisha Shah | H12: IS | K12: 5:00pm - 9:00pm | L12: Krisha Shah | M12: IS
A13: 9:00am - 1:00pm | B13: Kabilash | C13: IS | F13: 1:00pm - 5:00pm | G13: Kabilash | H13: IS | K13: 5:00pm - 9:00pm | L13: Kabilash | M13: IS
A14: 9:00am - 1:00pm | B14: Aaron Gao | C14: IS | F14: 1:00pm - 5:00pm | G14: Aaron Gao | H14: IS | K14: 5:00pm - 9:00pm | L14: Aaron Gao | M14: IS
A16: 9:00am - 1:00pm | B16: Alice Fei | C16: Mentor | D16: =counta(B16:B36) -> 19 | F16: 1:00pm - 5:00pm | G16: Alice Fei | H16: Mentor | I16: =counta(G16:G36) -> 19 | K16: 5:00pm - 9:00pm | L16: Ambrose Karklins | M16: Mentor | N16: =counta(L16:L36) -> 19
A17: 9:00am - 1:00pm | B17: Andrew Pang | C17: Mentor/Flex | F17: 1:00pm - 5:00pm | G17: Andrew Pang | H17: Mentor/Flex | K17: 5:00pm - 9:00pm | L17: Andrew Pang | M17: Mentor/Flex
A18: 9:00am - 1:00pm | B18: Anoja Kanagaruban | C18: Mentor | F18: 1:00pm - 5:00pm | G18: Audrey Lee | H18: Mentor/Flex | K18: 5:00pm - 9:00pm | L18: Anoja Kanagaruban | M18: Mentor
A19: 9:00am - 1:00pm | B19: Audrey Lee | C19: Mentor/Flex | F19: 1:00pm - 5:00pm | G19: Ben Crasto | H19: Mentor | K19: 5:00pm - 9:00pm | L19: Arjun Das | M19: Mentor
A20: 9:00am - 1:00pm | B20: Christina Nie | C20: Mentor | F20: 1:00pm - 5:00pm | G20: Bryon Lee | H20: Mentor/Flex | K20: 5:00pm - 9:00pm | L20: Audrey Lee | M20: Mentor/Flex
A21: 9:00am - 1:00pm | B21: Gia Zhou | C21: Mentor | F21: 1:00pm - 5:00pm | G21: Christina Nie | H21: Mentor | K21: 5:00pm - 9:00pm | L21: Ben Crasto | M21: Mentor
A22: 9:00am - 1:00pm | B22: Grace Harianto | C22: Mentor | F22: 1:00pm - 5:00pm | G22: Emma Li | H22: Mentor | K22: 5:00pm - 9:00pm | L22: Bryon Lee | M22: Mentor
F23: 1:00pm - 5:00pm | G23: Gia Zhou | H23: Mentor | K23: 5:00pm - 9:00pm | L23: Christina Nie | M23: Mentor
A24: 9:00am - 1:00pm | B24: Harper Zhang | C24: Mentor | F24: 1:00pm - 5:00pm | G24: Grace Harianto | H24: Mentor | K24: 5:00pm - 9:00pm | L24: Emma Li | M24: Mentor
A25: 9:00am - 1:00pm | B25: Harrison Liu | C25: Mentor | K25: 5:00pm - 9:00pm | L25: Harrison Liu | M25: Mentor
F26: 1:00pm - 5:00pm | G26: Harrison Liu | H26: Mentor | K26: 5:00pm - 9:00pm | L26: Helen Huang | M26: Mentor
A27: 9:00am - 1:00pm | B27: Kevin Pham | C27: Mentor/Flex | F27: 1:00pm - 5:00pm | G27: Jiale Deng | H27: Mentor | K27: 5:00pm - 9:00pm | L27: Kevin Pham | M27: Mentor/Flex
A28: 9:00am - 1:00pm | B28: Ryan Hui | C28: Mentor | K28: 5:00pm - 9:00pm | L28: Linda Li | M28: Mentor
A29: 9:00am - 1:00pm | B29: Shrey Patel | C29: Mentor | F29: 1:00pm - 5:00pm | G29: Linda Li | H29: Mentor | K29: 5:00pm - 9:00pm | L29: Mia Pang | M29: Mentor
A30: 9:00am - 1:00pm | B30: Steven Ye | C30: Mentor | F30: 1:00pm - 5:00pm | G30: Mia Pang | H30: Mentor | K30: 5:00pm - 9:00pm | L30: Mingrui Xu | M30: Mentor
A31: 9:00am - 1:00pm | B31: Tanreet Dharni | C31: Mentor | F31: 1:00pm - 5:00pm | G31: Mingrui Xu | H31: Mentor | K31: 5:00pm - 9:00pm | L31: Nihar Raval | M31: Mentor
A32: 9:00am - 1:00pm | B32: Vivian Lu | C32: Mentor | F32: 1:00pm - 5:00pm | G32: Nihar Raval | H32: Mentor
A33: 9:00am - 1:00pm | B33: Yizhen Chen | C33: Mentor/Flex | F33: 1:00pm - 5:00pm | G33: Steven Ye | H33: Mentor | K33: 5:00pm - 9:00pm | L33: Vanie Tran | M33: Mentor
A34: 9:00am - 1:00pm | B34: Jashan Gill | C34: Mentor | F34: 1:00pm - 5:00pm | G34: Vanie Tran | H34: Mentor | K34: 5:00pm - 9:00pm | L34: Yizhen Chen | M34: Mentor/Flex
A35: 9:00am - 1:00pm | B35: Qin Du | C35: Mentor | F35: 1:00pm - 5:00pm | G35: Yizhen Chen | H35: Mentor/Flex | K35: 5:00pm - 9:00pm | L35: Shane Balkaran | M35: Mentor
A36: 9:00am - 1:00pm | B36: Shane Balkaran | C36: Mentor | F36: 1:00pm - 5:00pm | G36: Jashan Gill | H36: Mentor
F37: 1:00pm - 5:00pm | G37: Shane Balkaran | H37: Mentor
A39: 9:00am - 1:00pm | B39: Adnan Nasiree | C39: Tax Filer | D39: =counta(B39:B102) -> 41 | F39: 1:00pm - 5:00pm | G39: Adnan Nasiree | H39: Tax Filer | I39: =counta(G39:G102) -> 52 | K39: 5:00pm - 9:00pm | L39: Abisha Vigneswaran | M39: Tax Filer | N39: =counta(L39:L102) -> 25
A40: 9:00am - 1:00pm | B40: Andrew Zulawski-Dayeh | C40: Tax Filer | F40: 1:00pm - 5:00pm | G40: Alex Hu | H40: Tax Filer | K40: 5:00pm - 9:00pm | L40: Alex Hu | M40: Tax Filer
A41: 9:00am - 1:00pm | B41: Aneil Ghosh | C41: Tax Filer | F41: 1:00pm - 5:00pm | G41: Andrew Zulawski-Dayeh | H41: Tax Filer | K41: 5:00pm - 9:00pm | M41: Tax Filer
A42: 9:00am - 1:00pm | B42: Anna Shields | C42: Tax Filer | F42: 1:00pm - 5:00pm | G42: Aneil Ghosh | H42: Tax Filer | K42: 5:00pm - 9:00pm | L42: Aryan Bhattacharjee | M42: Tax Filer
A43: 9:00am - 1:00pm | B43: Arthy Mathan | C43: Tax Filer | F43: 1:00pm - 5:00pm | G43: Anna Shields | H43: Tax Filer | K43: 5:00pm - 9:00pm | L43: Ashley Kim | M43: Tax Filer
...

Sheet March 30 - M3 1006
A1: Time | B1: Name | C1: Role | D1: Count | F1: Time | G1: First Name | H1: Role | I1: Count | K1: Time | L1: First Name | M1: Role | N1: Count
A2: Sum | D2: =sum(D3:D94) -> 63 | I2: =sum(I3:I94) -> 79 | N2: =sum(N3:N94) -> 42
A3: 9:00am - 1:00pm | B3: Aarushi Awasthi | C3: Receptionist | D3: =counta(B3:B5) -> 2 | F3: 1:00pm - 5:00pm | G3: Tiffany Ho | H3: Receptionist | I3: =counta(G3:G5) -> 2 | K3: 5:00pm - 9:00pm | L3: Kate Korsch | M3: Receptionist/Flex | N3: =counta(L3:L5) -> 1
A4: 9:00am - 1:00pm | B4: John Yung | C4: Receptionist/Mentor | F4: 1:00pm - 5:00pm | G4: John Yung | H4: Receptionist/Mentor
A9: 9:00am - 1:00pm | B9: Eric | C9: Tax Boss | D9: =counta(B9:B15) -> 7 | F9: 1:00pm - 5:00pm | G9: Eric | H9: Tax Boss | I9: =counta(G9:G15) -> 7 | K9: 5:00pm - 9:00pm | L9: Eric | M9: Tax Boss | N9: =counta(L9:L15) -> 7
A10: 9:00am - 1:00pm | B10: Rebecca | C10: Tax Guru | F10: 1:00pm - 5:00pm | G10: Rebecca | H10: Tax Guru | K10: 5:00pm - 9:00pm | L10: Rebecca | M10: Tax Guru
A11: 9:00am - 1:00pm | B11: Baldwyn Tai | C11: Tax Guru's Minion | F11: 1:00pm - 5:00pm | G11: Baldwyn Tai | H11: Tax Guru's Minion | K11: 5:00pm - 9:00pm | L11: Baldwyn Tai | M11: Tax Guru's Minion
A12: 9:00am - 1:00pm | B12: Ben | C12: Unemployed Tax Grunt | F12: 1:00pm - 5:00pm | G12: Ben | H12: Unemployed Tax Grunt | K12: 5:00pm - 9:00pm | L12: Ben | M12: Unemployed Tax Grunt
A13: 9:00am - 1:00pm | B13: Krisha Shah | C13: IS | F13: 1:00pm - 5:00pm | G13: Krisha Shah | H13: IS | K13: 5:00pm - 9:00pm | L13: Krisha Shah | M13: IS
A14: 9:00am - 1:00pm | B14: Kabilash | C14: IS | F14: 1:00pm - 5:00pm | G14: Kabilash | H14: IS | K14: 5:00pm - 9:00pm | L14: Kabilash | M14: IS
A15: 9:00am - 1:00pm | B15: Aaron Gao | C15: IS | F15: 1:00pm - 5:00pm | G15: Aaron Gao | H15: IS | K15: 5:00pm - 9:00pm | L15: Aaron Gao | M15: IS
A17: 9:00am - 1:00pm | B17: Andrew Pang | C17: Mentor/Flex | D17: =counta(B17:B38) -> 22 | F17: 1:00pm - 5:00pm | G17: Andrew Pang | H17: Mentor/Flex | I17: =counta(G17:G38) -> 22 | K17: 5:00pm - 9:00pm | L17: Andrew Pang | M17: Mentor/Flex | N17: =counta(L17:L38) -> 15
A18: 9:00am - 1:00pm | B18: Anastasija Kovacevic | C18: Mentor | F18: 1:00pm - 5:00pm | G18: Anastasija Kovacevic | H18: Mentor | K18: 5:00pm - 9:00pm | L18: Anastasija Kovacevic | M18: Mentor
A19: 9:00am - 1:00pm | B19: Audrey Lee | C19: Mentor/Flex | F19: 1:00pm - 5:00pm | G19: Audrey Lee | H19: Mentor/Flex | K19: 5:00pm - 9:00pm | L19: Ambrose Karklins | M19: Mentor
A20: 9:00am - 1:00pm | B20: Christina Nie | C20: Mentor | F20: 1:00pm - 5:00pm | G20: Christina Nie | H20: Mentor | K20: 5:00pm - 9:00pm | L20: Jake Li | M20: Mentor
A21: 9:00am - 1:00pm | B21: Ambrose Karklins | C21: Mentor | F21: 1:00pm - 5:00pm | G21: Ambrose Karklins | H21: Mentor | K21: 5:00pm - 9:00pm | L21: Kevin Pham | M21: Mentor
A22: 9:00am - 1:00pm | B22: Harrison Liu | C22: Mentor | F22: 1:00pm - 5:00pm | G22: Jadon Xu | H22: Mentor | K22: 5:00pm - 9:00pm | L22: Qin Du | M22: Mentor
A23: 9:00am - 1:00pm | B23: Jadon Xu | C23: Mentor | F23: 1:00pm - 5:00pm | G23: Jake Li | H23: Mentor | K23: 5:00pm - 9:00pm | L23: Maryam Awad | M23: Mentor
A24: 9:00am - 1:00pm | B24: Kevin Pham | C24: Mentor | F24: 1:00pm - 5:00pm | G24: Vanie Tran | H24: Mentor | K24: 5:00pm - 9:00pm | L24: Natalia Ruiz | M24: Mentor
A25: 9:00am - 1:00pm | B25: Vanie Tran | C25: Mentor | F25: 1:00pm - 5:00pm | G25: Clement Huang | H25: Mentor | K25: 5:00pm - 9:00pm | L25: Tanreet Dharni | M25: Mentor
A26: 9:00am - 1:00pm | B26: Qin Du | C26: Mentor | F26: 1:00pm - 5:00pm | G26: Maryam Awad | H26: Mentor | K26: 5:00pm - 9:00pm | L26: Darnisa Ratnalingam | M26: Mentor
A27: 9:00am - 1:00pm | B27: Arjun Das | C27: Mentor | F27: 1:00pm - 5:00pm | G27: Natalia Ruiz | H27: Mentor | K27: 5:00pm - 9:00pm | L27: Yizhen Chen | M27: Mentor/Flex
A28: 9:00am - 1:00pm | B28: Clement Huang | C28: Mentor | F28: 1:00pm - 5:00pm | G28: Saniya Nag | H28: Mentor | K28: 5:00pm - 9:00pm | L28: Claire Kennedy | M28: Mentor
A29: 9:00am - 1:00pm | B29: Helen Huang | C29: Mentor | F29: 1:00pm - 5:00pm | G29: Nathan Woods | H29: Mentor | K29: 5:00pm - 9:00pm | L29: Mica Hua | M29: Mentor
... A31: 9:00am - 1:00pm | B31: Timothy Chen | C31: Mentor | F31: 1:00pm - 5:00pm | G31: Darnisa Ratnalingam | H31: Mentor | K31: 1:00pm - 5:00pm | L31: Shane Balkaran | M31: Mentor
A32: 9:00am - 1:00pm | B32: Darnisa Ratnalingam | C32: Mentor | F32: 1:00pm - 5:00pm | G32: Yizhen Chen | H32: Mentor/Flex
A33: 9:00am - 1:00pm | B33: Yizhen Chen | C33: Mentor/Flex | F33: 1:00pm - 5:00pm | G33: Aimée Boulay | H33: Mentor
A34: 9:00am - 1:00pm | B34: Aimée Boulay | C34: Mentor | F34: 1:00pm - 5:00pm | G34: Claire Kennedy | H34: Mentor
A35: 9:00am - 1:00pm | B35: Heer Patel | C35: Mentor | F35: 1:00pm - 5:00pm | G35: Heer Patel | H35: Mentor
A36: 9:00am - 1:00pm | B36: Muhammad Wasif | C36: Mentor | F36: 1:00pm - 5:00pm | G36: Mica Hua | H36: Mentor
A37: 9:00am - 1:00pm | B37: Samee Haque | C37: Mentor | F37: 1:00pm - 5:00pm | G37: Muhammad Wasif | H37: Mentor
A38: 9:00am - 1:00pm | B38: Jashan Gill | C38: Mentor | F38: 1:00pm - 5:00pm | G38: Samee Haque | H38: Mentor
A39: 9:00am - 1:00pm | B39: Shane Balkaran | C39: Mentor | F39: 1:00pm - 5:00pm | G39: Shane Balkaran | H39: Mentor
A40: 9:00am - 1:00pm | B40: Seniru De Silva | C40: Mentor
A42: 9:00am - 1:00pm | B42: Andrew Zulawski-Dayeh | C42: Tax Filer | D42: =counta(B42:B105) -> 32 | F42: 1:00pm - 5:00pm | G42: Adnan Nasiree | H42: Tax Filer | I42: =counta(G42:G105) -> 48 | K42: 5:00pm - 9:00pm | L42: Andy Nguyen | M42: Tax Filer | N42: =counta(L42:L105) -> 19
A43: 9:00am - 1:00pm | B43: Aneil Ghosh | C43: Tax Filer | F43: 1:00pm - 5:00pm | G43: Andrew Zulawski-Dayeh | H43: Tax Filer | K43: 5:00pm - 9:00pm | L43: Annie Chen | M43: Tax Filer
A44: 9:00am - 1:00pm | B44: Anna Shields | C44: Tax Filer | F44: 1:00pm - 5:00pm | G44: Andy Nguyen | H44: Tax Filer | K44: 5:00pm - 9:00pm | L44: Aryan Bhattacharjee | M44: Tax Filer
A45: 9:00am - 1:00pm | B45: Annie Chen | C45: Tax Filer | F45: 1:00pm - 5:00pm | G45: Anna Shields | H45: Tax Filer | K45: 5:00pm - 9:00pm | L45: Brody Sidaway | M45: Tax Filer
A46: 9:00am - 1:00pm | B46: Arthy Mathan | C46: Tax Filer | F46: 1:00pm - 5:00pm | G46: Annie Chen | H46: Tax Filer | K46: 5:00pm - 9:00pm | L46: Edwina Li | M46: Tax Filer
A47: 9:00am - 1:00pm | B47: Brody Sidaway | C47: Tax Filer | F47: 1:00pm - 5:00pm | G47: Aryan Bhattacharjee | H47: Tax Filer | K47: 5:00pm - 9:00pm | L47: Hannah Nguyen | M47: Tax Filer
...

Sheet By Name
A1: Full Name | B1: Count of shifts assigned | C1: Saturday March 22nd, 9:00am - 1:00pm RCH 301 | D1: Saturday March 22nd, 1:00pm - 5:00 pm RCH 301 | E1: Saturday March 22nd, 5:00pm - 9:00pm RCH 301 | F1: Sunday March 23rd, 9:00am - 1:00pm M3 1006 | G1: Sunday March 23rd, 1:00pm - 5:00pm M3 1006 | H1: Sunday March 23rd, 5:00pm - 9:00pm M3 1006 | I1: Saturday March 29th, 9:00am - 1:00pm M3 1006 | J1: Saturday March 29th, 1:00pm - 5:00pm M3 1006 | K1: Saturday March 29th, 5:00pm - 9:00pm M3 1006 | L1: Sunday March 30th, 9:00am - 1:00pm M3 1006 | M1: Sunday March 30th, 1:00pm - 5:00pm M3 1006 | N1: Sunday March 30th, 5:00pm - 9:00pm M3 1006
A2: Amy Cheung | B2: =countif(C2:N2,"o") -> 2 | C2: =if(iferror(match(A2,'March 22 - RCH 301'!B:B,0),FALSE),"o","") -> o | D2: =if(iferror(match(A2,'March 22 - RCH 301'!G:G,0),FALSE),"o","") -> o | E2: =if(iferror(match(A2,'March 22 - RCH 301'!L:L,0),FALSE),"o","") | F2: =if(iferror(match(A2,'March 23 - M3 1006'!B:B,0),FALSE),"o","") | G2: =if(iferror(match(A2,'March 23 - M3 1006'!G:G,0),FALSE),"o","") | H2: =if(iferror(match(A2,'March 23 - M3 1006'!L:L,0),FALSE),"o","") | I2: =if(iferror(match(A2,'March 29 - M3 1006'!B:B,0),FALSE),"o","") | J2: =if(iferror(match(A2,'March 29 - M3 1006'!G:G,0),FALSE),"o","") | K2: =if(iferror(match(A2,'March 29 - M3 1006'!L:L,0),FALSE),"o","") | L2: =if(iferror(match(A2,'March 30 - M3 1006'!B:B,0),FALSE),"o","") | M2: =if(iferror(match(A2,'March 30 - M3 1006'!G:G,0),FALSE),"o","") | N2: =if(iferror(match(A2,'March 30 - M3 1006'!L:L,0),FALSE),"o","")
A3: Andrew Pang | B3: =countif(C3:N3,"o") -> 12 | C3: =if(iferror(match(A3,'March 22 - RCH 301'!B:B,0),FALSE),"o","") -> o | D3: =if(iferror(match(A3,'March 22 - RCH 301'!G:G,0),FALSE),"o","") -> o | E3: =if(iferror(match(A3,'March 22 - RCH 301'!L:L,0),FALSE),"o","") -> o | F3: =if(iferror(match(A3,'March 23 - M3 1006'!B:B,0),FALSE),"o","") -> o | G3: =if(iferror(match(A3,'March 23 - M3 1006'!G:G,0),FALSE),"o","") -> o | H3: =if(iferror(match(A3,'March 23 - M3 1006'!L:L,0),FALSE),"o","") -> o | I3: =if(iferror(match(A3,'March 29 - M3 1006'!B:B,0),FALSE),"o","") -> o | J3: =if(iferror(match(A3,'March 29 - M3 1006'!G:G,0),FALSE),"o","") -> o | K3: =if(iferror(match(A3,'March 29 - M3 1006'!L:L,0),FALSE),"o","") -> o | L3: =if(iferror(match(A3,'March 30 - M3 1006'!B:B,0),FALSE),"o","") -> o | M3: =if(iferror(match(A3,'March 30 - M3 1006'!G:G,0),FALSE),"o","") -> o | N3: =if(iferror(match(A3,'March 30 - M3 1006'!L:L,0),FALSE),"o","") -> o
A4: Aurora Wang | B4: =countif(C4:N4,"o") -> 6 | C4: =if(iferror(match(A4,'March 22 - RCH 301'!B:B,0),FALSE),"o","") -> o | D4: =if(iferror(match(A4,'March 22 - RCH 301'!G:G,0),FALSE),"o","") -> o | E4: =if(iferror(match(A4,'March 22 - RCH 301'!L:L,0),FALSE),"o","") -> o | F4: =if(iferror(match(A4,'March 23 - M3 1006'!B:B,0),FALSE),"o","") -> o | G4: =if(iferror(match(A4,'March 23 - M3 1006'!G:G,0),FALSE),"o","") -> o | H4: =if(iferror(match(A4,'March 23 - M3 1006'!L:L,0),FALSE),"o","") -> o | I4: =if(iferror(match(A4,'March 29 - M3 1006'!B:B,0),FALSE),"o","") | J4: =if(iferror(match(A4,'March 29 - M3 1006'!G:G,0),FALSE),"o","") | K4: =if(iferror(match(A4,'March 29 - M3 1006'!L:L,0),FALSE),"o","") | L4: =if(iferror(match(A4,'March 30 - M3 1006'!B:B,0),FALSE),"o","") | M4: =if(iferror(match(A4,'March 30 - M3 1006'!G:G,0),FALSE),"o","") | N4: =if(iferror(match(A4,'March 30 - M3 1006'!L:L,0),FALSE),"o","")
A5: Anastasija Kovacevic | B5: =countif(C5:N5,"o") -> 6 | C5: =if(iferror(match(A5,'March 22 - RCH 301'!B:B,0),FALSE),"o","") | D5: =if(iferror(match(A5,'March 22 - RCH 301'!G:G,0),FALSE),"o","") | E5: =if(iferror(match(A5,'March 22 - RCH 301'!L:L,0),FALSE),"o","") | F5: =if(iferror(match(A5,'March 23 - M3 1006'!B:B,0),FALSE),"o","") -> o | G5: =if(iferror(match(A5,'March 23 - M3 1006'!G:G,0),FALSE),"o","") -> o | H5: =if(iferror(match(A5,'March 23 - M3 1006'!L:L,0),FALSE),"o","") -> o | I5: =if(iferror(match(A5,'March 29 - M3 1006'!B:B,0),FALSE),"o","") | J5: =if(iferror(match(A5,'March 29 - M3 1006'!G:G,0),FALSE),"o","") | K5: =if(iferror(match(A5,'March 29 - M3 1006'!L:L,0),FALSE),"o","") | L5: =if(iferror(match(A5,'March 30 - M3 1006'!B:B,0),FALSE),"o","") -> o | M5: =if(iferror(match(A5,'March 30 - M3 1006'!G:G,0),FALSE),"o","") -> o | N5: =if(iferror(match(A5,'March 30 - M3 1006'!L:L,0),FALSE),"o","") -> o
A6: Audrey Lee | B6: =countif(C6:N6,"o") -> 12 | C6: =if(iferror(match(A6,'March 22 - RCH 301'!B:B,0),FALSE),"o","") -> o | D6: =if(iferror(match(A6,'March 22 - RCH 301'!G:G,0),FALSE),"o","") -> o | E6: =if(iferror(match(A6,'March 22 - RCH 301'!L:L,0),FALSE),"o","") -> o | F6: =if(iferror(match(A6,'March 23 - M3 1006'!B:B,0),FALSE),"o","") -> o | G6: =if(iferror(match(A6,'March 23 - M3 1006'!G:G,0),FALSE),"o","") -> o | H6: =if(iferror(match(A6,'March 23 - M3 1006'!L:L,0),FALSE),"o","") -> o | I6: =if(iferror(match(A6,'March 29 - M3 1006'!B:B,0),FALSE),"o","") -> o | J6: =if(iferror(match(A6,'March 29 - M3 1006'!G:G,0),FALSE),"o","") -> o | K6: =if(iferror(match(A6,'March 29 - M3 1006'!L:L,0),FALSE),"o","") -> o | L6: =if(iferror(match(A6,'March 30 - M3 1006'!B:B,0),FALSE),"o","") -> o | M6: =if(iferror(match(A6,'March 30 - M3 1006'!G:G,0),FALSE),"o","") -> o | N6: =if(iferror(match(A6,'March 30 - M3 1006'!L:L,0),FALSE),"o","") -> o
A7: Christina Nie | B7: =countif(C7:N7,"o") -> 10 | C7: =if(iferror(match(A7,'March 22 - RCH 301'!B:B,0),FALSE),"o","") -> o | D7: =if(iferror(match(A7,'March 22 - RCH 301'!G:G,0),FALSE),"o","") -> o | E7: =if(iferror(match(A7,'March 22 - RCH 301'!L:L,0),FALSE),"o","") -> o | F7: =if(iferror(match(A7,'March 23 - M3 1006'!B:B,0),FALSE),"o","") -> o | G7: =if(iferror(match(A7,'March 23 - M3 1006'!G:G,0),FALSE),"o","") -> o | H7: =if(iferror(match(A7,'March 23 - M3 1006'!L:L,0),FALSE),"o","") | I7: =if(iferror(match(A7,'March 29 - M3 1006'!B:B,0),FALSE),"o","") -> o | J7: =if(iferror(match(A7,'March 29 - M3 1006'!G:G,0),FALSE),"o","") -> o | K7: =if(iferror(match(A7,'March 29 - M3 1006'!L:L,0),FALSE),"o","") -> o | L7: =if(iferror(match(A7,'March 30 - M3 1006'!B:B,0),FALSE),"o","") -> o | M7: =if(iferror(match(A7,'March 30 - M3 1006'!G:G,0),FALSE),"o","") -> o | N7: =if(iferror(match(A7,'March 30 - M3 1006'!L:L,0),FALSE),"o","")
A8: Ambrose Karklins | B8: =countif(C8:N8,"o") -> 7 | C8: =if(iferror(match(A8,'March 22 - RCH 301'!B:B,0),FALSE),"o","") | D8: =if(iferror(match(A8,'March 22 - RCH 301'!G:G,0),FALSE),"o","") | E8: =if(iferror(match(A8,'March 22 - RCH 301'!L:L,0),FALSE),"o","") | F8: =if(iferror(match(A8,'March 23 - M3 1006'!B:B,0),FALSE),"o","") -> o | G8: =if(iferror(match(A8,'March 23 - M3 1006'!G:G,0),FALSE),"o","") -> o | H8: =if(iferror(match(A8,'March 23 - M3 1006'!L:L,0),FALSE),"o","") -> o | I8: =if(iferror(match(A8,'March 29 - M3 1006'!B:B,0),FALSE),"o","") | J8: =if(iferror(match(A8,'March 29 - M3 1006'!G:G,0),FALSE),"o","") | K8: =if(iferror(match(A8,'March 29 - M3 1006'!L:L,0),FALSE),"o","") -> o | L8: =if(iferror(match(A8,'March 30 - M3 1006'!B:B,0),FALSE),"o","") -> o | M8: =if(iferror(match(A8,'March 30 - M3 1006'!G:G,0),FALSE),"o","") -> o | N8: =if(iferror(match(A8,'March 30 - M3 1006'!L:L,0),FALSE),"o","") -> o
A9: Harper Zhang | B9: =countif(C9:N9,"o") -> 2 | C9: =if(iferror(match(A9,'March 22 - RCH 301'!B:B,0),FALSE),"o","") -> o | D9: =if(iferror(match(A9,'March 22 - RCH 301'!G:G,0),FALSE),"o","") | E9: =if(iferror(match(A9,'March 22 - RCH 301'!L:L,0),FALSE),"o","") | F9: =if(iferror(match(A9,'March 23 - M3 1006'!B:B,0),FALSE),"o","") | G9: =if(iferror(match(A9,'March 23 - M3 1006'!G:G,0),FALSE),"o","") | H9: =if(iferror(match(A9,'March 23 - M3 1006'!L:L,0),FALSE),"o","") | I9: =if(iferror(match(A9,'March 29 - M3 1006'!B:B,0),FALSE),"o","") -> o | J9: =if(iferror(match(A9,'March 29 - M3 1006'!G:G,0),FALSE),"o","") | K9: =if(iferror(match(A9,'March 29 - M3 1006'!L:L,0),FALSE),"o","") | L9: =if(iferror(match(A9,'March 30 - M3 1006'!B:B,0),FALSE),"o","") | M9: =if(iferror(match(A9,'March 30 - M3 1006'!G:G,0),FALSE),"o","") | N9: =if(iferror(match(A9,'March 30 - M3 1006'!L:L,0),FALSE),"o","")
A10: Harrison Liu | B10: =countif(C10:N10,"o") -> 4 | C10: =if(iferror(match(A10,'March 22 - RCH 301'!B:B,0),FALSE),"o","") | D10: =if(iferror(match(A10,'March 22 - RCH 301'!G:G,0),FALSE),"o","") | E10: =if(iferror(match(A10,'March 22 - RCH 301'!L:L,0),FALSE),"o","") | F10: =if(iferror(match(A10,'March 23 - M3 1006'!B:B,0),FALSE),"o","") | G10: =if(iferror(match(A10,'March 23 - M3 1006'!G:G,0),FALSE),"o","") | H10: =if(iferror(match(A10,'March 23 - M3 1006'!L:L,0),FALSE),"o","") | I10: =if(iferror(match(A10,'March 29 - M3 1006'!B:B,0),FALSE),"o","") -> o | J10: =if(iferror(match(A10,'March 29 - M3 1006'!G:G,0),FALSE),"o","") -> o | K10: =if(iferror(match(A10,'March 29 - M3 1006'!L:L,0),FALSE),"o","") -> o | L10: =if(iferror(match(A10,'March 30 - M3 1006'!B:B,0),FALSE),"o","") -> o | M10: =if(iferror(match(A10,'March 30 - M3 1006'!G:G,0),FALSE),"o","") | N10: =if(iferror(match(A10,'March 30 - M3 1006'!L:L,0),FALSE),"o","")
A11: Jadon Xu | B11: =countif(C11:N11,"o") -> 6 | C11: =if(iferror(match(A11,'March 22 - RCH 301'!B:B,0),FALSE),"o","") -> o | D11: =if(iferror(match(A11,'March 22 - RCH 301'!G:G,0),FALSE),"o","") -> o | E11: =if(iferror(match(A11,'March 22 - RCH 301'!L:L,0),FALSE),"o","") | F11: =if(iferror(match(A11,'March 23 - M3 1006'!B:B,0),FALSE),"o","") -> o | G11: =if(iferror(match(A11,'March 23 - M3 1006'!G:G,0),FALSE),"o","") -> o | H11: =if(iferror(match(A11,'March 23 - M3 1006'!L:L,0),FALSE),"o","") | I11: =if(iferror(match(A11,'March 29 - M3 1006'!B:B,0),FALSE),"o","") | J11: =if(iferror(match(A11,'March 29 - M3 1006'!G:G,0),FALSE),"o","") | K11: =if(iferror(match(A11,'March 29 - M3 1006'!L:L,0),FALSE),"o","") | L11: =if(iferror(match(A11,'March 30 - M3 1006'!B:B,0),FALSE),"o","") -> o | M11: =if(iferror(match(A11,'March 30 - M3 1006'!G:G,0),FALSE),"o","") -> o | N11: =if(iferror(match(A11,'March 30 - M3 1006'!L:L,0),FALSE),"o","")
A12: Jake Li | B12: =countif(C12:N12,"o") -> 4 | C12: =if(iferror(match(A12,'March 22 - RCH 301'!B:B,0),FALSE),"o","") | D12: =if(iferror(match(A12,'March 22 - RCH 301'!G:G,0),FALSE),"o","") | E12: =if(iferror(match(A12,'March 22 - RCH 301'!L:L,0),FALSE),"o","") | F12: =if(iferror(match(A12,'March 23 - M3 1006'!B:B,0),FALSE),"o","") | G12: =if(iferror(match(A12,'March 23 - M3 1006'!G:G,0),FALSE),"o","") -> o | H12: =if(iferror(match(A12,'March 23 - M3 1006'!L:L,0),FALSE),"o","") -> o | I12: =if(iferror(match(A12,'March 29 - M3 1006'!B:B,0),FALSE),"o","") | J12: =if(iferror(match(A12,'March 29 - M3 1006'!G:G,0),FALSE),"o","") | K12: =if(iferror(match(A12,'March 29 - M3 1006'!L:L,0),FALSE),"o","") | L12: =if(iferror(match(A12,'March 30 - M3 1006'!B:B,0),FALSE),"o","") | M12: =if(iferror(match(A12,'March 30 - M3 1006'!G:G,0),FALSE),"o","") -> o | N12: =if(iferror(match(A12,'March 30 - M3 1006'!L:L,0),FALSE),"o","") -> o
A13: Kevin Pham | B13: =countif(C13:N13,"o") -> 10 | C13: =if(iferror(match(A13,'March 22 - RCH 301'!B:B,0),FALSE),"o","") -> o | D13: =if(iferror(match(A13,'March 22 - RCH 301'!G:G,0),FALSE),"o","") -> o | E13: =if(iferror(match(A13,'March 22 - RCH 301'!L:L,0),FALSE),"o","") -> o | F13: =if(iferror(match(A13,'March 23 - M3 1006'!B:B,0),FALSE),"o","") -> o | G13: =if(iferror(match(A13,'March 23 - M3 1006'!G:G,0),FALSE),"o","") -> o | H13: =if(iferror(match(A13,'March 23 - M3 1006'!L:L,0),FALSE),"o","") -> o | I13: =if(iferror(match(A13,'March 29 - M3 1006'!B:B,0),FALSE),"o","") -> o | J13: =if(iferror(match(A13,'March 29 - M3 1006'!G:G,0),FALSE),"o","") | K13: =if(iferror(match(A13,'March 29 - M3 1006'!L:L,0),FALSE),"o","") -> o | L13: =if(iferror(match(A13,'March 30 - M3 1006'!B:B,0),FALSE),"o","") -> o | M13: =if(iferror(match(A13,'March 30 - M3 1006'!G:G,0),FALSE),"o","") | N13: =if(iferror(match(A13,'March 30 - M3 1006'!L:L,0),FALSE),"o","") -> o
... A199: Rina Lad | B199: =countif(C199:N199,"o") -> 3 | C199: =if(iferror(match(A199,'March 22 - RCH 301'!B:B,0),FALSE),"o","") | D199: =if(iferror(match(A199,'March 22 - RCH 301'!G:G,0),FALSE),"o","") | E199: =if(iferror(match(A199,'March 22 - RCH 301'!L:L,0),FALSE),"o","") | F199: =if(iferror(match(A199,'March 23 - M3 1006'!B:B,0),FALSE),"o","") -> o | G199: =if(iferror(match(A199,'March 23 - M3 1006'!G:G,0),FALSE),"o","") -> o | H199: =if(iferror(match(A199,'March 23 - M3 1006'!L:L,0),FALSE),"o","") -> o | I199: =if(iferror(match(A199,'March 29 - M3 1006'!B:B,0),FALSE),"o","") | J199: =if(iferror(match(A199,'March 29 - M3 1006'!G:G,0),FALSE),"o","") | K199: =if(iferror(match(A199,'March 29 - M3 1006'!L:L,0),FALSE),"o","") | L199: =if(iferror(match(A199,'March 30 - M3 1006'!B:B,0),FALSE),"o","") | M199: =if(iferror(match(A199,'March 30 - M3 1006'!G:G,0),FALSE),"o","") | N199: =if(iferror(match(A199,'March 30 - M3 1006'!L:L,0),FALSE),"o","")
A200: Nadia Mesfin | C200: =if(iferror(match(A200,'March 22 - RCH 301'!B:B,0),FALSE),"o","") | D200: =if(iferror(match(A200,'March 22 - RCH 301'!G:G,0),FALSE),"o","") | E200: =if(iferror(match(A200,'March 22 - RCH 301'!L:L,0),FALSE),"o","") | F200: =if(iferror(match(A200,'March 23 - M3 1006'!B:B,0),FALSE),"o","") -> o | G200: =if(iferror(match(A200,'March 23 - M3 1006'!G:G,0),FALSE),"o","") -> o | H200: =if(iferror(match(A200,'March 23 - M3 1006'!L:L,0),FALSE),"o","") | I200: =if(iferror(match(A200,'March 29 - M3 1006'!B:B,0),FALSE),"o","") -> o | J200: =if(iferror(match(A200,'March 29 - M3 1006'!G:G,0),FALSE),"o","") | K200: =if(iferror(match(A200,'March 29 - M3 1006'!L:L,0),FALSE),"o","") | L200: =if(iferror(match(A200,'March 30 - M3 1006'!B:B,0),FALSE),"o","") -> o | M200: =if(iferror(match(A200,'March 30 - M3 1006'!G:G,0),FALSE),"o","") | N200: =if(iferror(match(A200,'March 30 - M3 1006'!L:L,0),FALSE),"o","")
A201: Alyson Chin | C201: =if(iferror(match(A201,'March 22 - RCH 301'!B:B,0),FALSE),"o","") | D201: =if(iferror(match(A201,'March 22 - RCH 301'!G:G,0),FALSE),"o","") | E201: =if(iferror(match(A201,'March 22 - RCH 301'!L:L,0),FALSE),"o","") | F201: =if(iferror(match(A201,'March 23 - M3 1006'!B:B,0),FALSE),"o","") -> o | G201: =if(iferror(match(A201,'March 23 - M3 1006'!G:G,0),FALSE),"o","") -> o | H201: =if(iferror(match(A201,'March 23 - M3 1006'!L:L,0),FALSE),"o","") -> o | I201: =if(iferror(match(A201,'March 29 - M3 1006'!B:B,0),FALSE),"o","") | J201: =if(iferror(match(A201,'March 29 - M3 1006'!G:G,0),FALSE),"o","") | K201: =if(iferror(match(A201,'March 29 - M3 1006'!L:L,0),FALSE),"o","") | L201: =if(iferror(match(A201,'March 30 - M3 1006'!B:B,0),FALSE),"o","") | M201: =if(iferror(match(A201,'March 30 - M3 1006'!G:G,0),FALSE),"o","") | N201: =if(iferror(match(A201,'March 30 - M3 1006'!L:L,0),FALSE),"o","")
A202: Shane Balkaran | C202: =if(iferror(match(A202,'March 22 - RCH 301'!B:B,0),FALSE),"o","") | D202: =if(iferror(match(A202,'March 22 - RCH 301'!G:G,0),FALSE),"o","") | E202: =if(iferror(match(A202,'March 22 - RCH 301'!L:L,0),FALSE),"o","") | F202: =if(iferror(match(A202,'March 23 - M3 1006'!B:B,0),FALSE),"o","") -> o | G202: =if(iferror(match(A202,'March 23 - M3 1006'!G:G,0),FALSE),"o","") | H202: =if(iferror(match(A202,'March 23 - M3 1006'!L:L,0),FALSE),"o","") -> o | I202: =if(iferror(match(A202,'March 29 - M3 1006'!B:B,0),FALSE),"o","") -> o | J202: =if(iferror(match(A202,'March 29 - M3 1006'!G:G,0),FALSE),"o","") -> o | K202: =if(iferror(match(A202,'March 29 - M3 1006'!L:L,0),FALSE),"o","") -> o | L202: =if(iferror(match(A202,'March 30 - M3 1006'!B:B,0),FALSE),"o","") -> o | M202: =if(iferror(match(A202,'March 30 - M3 1006'!G:G,0),FALSE),"o","") -> o | N202: =if(iferror(match(A202,'March 30 - M3 1006'!L:L,0),FALSE),"o","") -> o
C203: =if(iferror(match(A203,'March 22 - RCH 301'!B:B,0),FALSE),"o","") | D203: =if(iferror(match(A203,'March 22 - RCH 301'!G:G,0),FALSE),"o","") | E203: =if(iferror(match(A203,'March 22 - RCH 301'!L:L,0),FALSE),"o","") | F203: =if(iferror(match(A203,'March 23 - M3 1006'!B:B,0),FALSE),"o","") | G203: =if(iferror(match(A203,'March 23 - M3 1006'!G:G,0),FALSE),"o","") | H203: =if(iferror(match(A203,'March 23 - M3 1006'!L:L,0),FALSE),"o","") | I203: =if(iferror(match(A203,'March 29 - M3 1006'!B:B,0),FALSE),"o","") | J203: =if(iferror(match(A203,'March 29 - M3 1006'!G:G,0),FALSE),"o","") | K203: =if(iferror(match(A203,'March 29 - M3 1006'!L:L,0),FALSE),"o","") | L203: =if(iferror(match(A203,'March 30 - M3 1006'!B:B,0),FALSE),"o","") | M203: =if(iferror(match(A203,'March 30 - M3 1006'!G:G,0),FALSE),"o","") | N203: =if(iferror(match(A203,'March 30 - M3 1006'!L:L,0),FALSE),"o","")
C204: =if(iferror(match(A204,'March 22 - RCH 301'!B:B,0),FALSE),"o","") | D204: =if(iferror(match(A204,'March 22 - RCH 301'!G:G,0),FALSE),"o","") | E204: =if(iferror(match(A204,'March 22 - RCH 301'!L:L,0),FALSE),"o","") | F204: =if(iferror(match(A204,'March 23 - M3 1006'!B:B,0),FALSE),"o","") | G204: =if(iferror(match(A204,'March 23 - M3 1006'!G:G,0),FALSE),"o","") | H204: =if(iferror(match(A204,'March 23 - M3 1006'!L:L,0),FALSE),"o","") | I204: =if(iferror(match(A204,'March 29 - M3 1006'!B:B,0),FALSE),"o","") | J204: =if(iferror(match(A204,'March 29 - M3 1006'!G:G,0),FALSE),"o","") | K204: =if(iferror(match(A204,'March 29 - M3 1006'!L:L,0),FALSE),"o","") | L204: =if(iferror(match(A204,'March 30 - M3 1006'!B:B,0),FALSE),"o","") | M204: =if(iferror(match(A204,'March 30 - M3 1006'!G:G,0),FALSE),"o","") | N204: =if(iferror(match(A204,'March 30 - M3 1006'!L:L,0),FALSE),"o","")
C205: =if(iferror(match(A205,'March 22 - RCH 301'!B:B,0),FALSE),"o","") | D205: =if(iferror(match(A205,'March 22 - RCH 301'!G:G,0),FALSE),"o","") | E205: =if(iferror(match(A205,'March 22 - RCH 301'!L:L,0),FALSE),"o","") | F205: =if(iferror(match(A205,'March 23 - M3 1006'!B:B,0),FALSE),"o","") | G205: =if(iferror(match(A205,'March 23 - M3 1006'!G:G,0),FALSE),"o","") | H205: =if(iferror(match(A205,'March 23 - M3 1006'!L:L,0),FALSE),"o","") | I205: =if(iferror(match(A205,'March 29 - M3 1006'!B:B,0),FALSE),"o","") | J205: =if(iferror(match(A205,'March 29 - M3 1006'!G:G,0),FALSE),"o","") | K205: =if(iferror(match(A205,'March 29 - M3 1006'!L:L,0),FALSE),"o","") | L205: =if(iferror(match(A205,'March 30 - M3 1006'!B:B,0),FALSE),"o","") | M205: =if(iferror(match(A205,'March 30 - M3 1006'!G:G,0),FALSE),"o","") | N205: =if(iferror(match(A205,'March 30 - M3 1006'!L:L,0),FALSE),"o","")
C206: =if(iferror(match(A206,'March 22 - RCH 301'!B:B,0),FALSE),"o","") | D206: =if(iferror(match(A206,'March 22 - RCH 301'!G:G,0),FALSE),"o","") | E206: =if(iferror(match(A206,'March 22 - RCH 301'!L:L,0),FALSE),"o","") | F206: =if(iferror(match(A206,'March 23 - M3 1006'!B:B,0),FALSE),"o","") | G206: =if(iferror(match(A206,'March 23 - M3 1006'!G:G,0),FALSE),"o","") | H206: =if(iferror(match(A206,'March 23 - M3 1006'!L:L,0),FALSE),"o","") | I206: =if(iferror(match(A206,'March 29 - M3 1006'!B:B,0),FALSE),"o","") | J206: =if(iferror(match(A206,'March 29 - M3 1006'!G:G,0),FALSE),"o","") | K206: =if(iferror(match(A206,'March 29 - M3 1006'!L:L,0),FALSE),"o","") | L206: =if(iferror(match(A206,'March 30 - M3 1006'!B:B,0),FALSE),"o","") | M206: =if(iferror(match(A206,'March 30 - M3 1006'!G:G,0),FALSE),"o","") | N206: =if(iferror(match(A206,'March 30 - M3 1006'!L:L,0),FALSE),"o","")
C207: =if(iferror(match(A207,'March 22 - RCH 301'!B:B,0),FALSE),"o","") | D207: =if(iferror(match(A207,'March 22 - RCH 301'!G:G,0),FALSE),"o","") | E207: =if(iferror(match(A207,'March 22 - RCH 301'!L:L,0),FALSE),"o","") | F207: =if(iferror(match(A207,'March 23 - M3 1006'!B:B,0),FALSE),"o","") | G207: =if(iferror(match(A207,'March 23 - M3 1006'!G:G,0),FALSE),"o","") | H207: =if(iferror(match(A207,'March 23 - M3 1006'!L:L,0),FALSE),"o","") | I207: =if(iferror(match(A207,'March 29 - M3 1006'!B:B,0),FALSE),"o","") | J207: =if(iferror(match(A207,'March 29 - M3 1006'!G:G,0),FALSE),"o","") | K207: =if(iferror(match(A207,'March 29 - M3 1006'!L:L,0),FALSE),"o","") | L207: =if(iferror(match(A207,'March 30 - M3 1006'!B:B,0),FALSE),"o","") | M207: =if(iferror(match(A207,'March 30 - M3 1006'!G:G,0),FALSE),"o","") | N207: =if(iferror(match(A207,'March 30 - M3 1006'!L:L,0),FALSE),"o","")
C208: =if(iferror(match(A208,'March 22 - RCH 301'!B:B,0),FALSE),"o","") | D208: =if(iferror(match(A208,'March 22 - RCH 301'!G:G,0),FALSE),"o","") | E208: =if(iferror(match(A208,'March 22 - RCH 301'!L:L,0),FALSE),"o","") | F208: =if(iferror(match(A208,'March 23 - M3 1006'!B:B,0),FALSE),"o","") | G208: =if(iferror(match(A208,'March 23 - M3 1006'!G:G,0),FALSE),"o","") | H208: =if(iferror(match(A208,'March 23 - M3 1006'!L:L,0),FALSE),"o","") | I208: =if(iferror(match(A208,'March 29 - M3 1006'!B:B,0),FALSE),"o","") | J208: =if(iferror(match(A208,'March 29 - M3 1006'!G:G,0),FALSE),"o","") | K208: =if(iferror(match(A208,'March 29 - M3 1006'!L:L,0),FALSE),"o","") | L208: =if(iferror(match(A208,'March 30 - M3 1006'!B:B,0),FALSE),"o","") | M208: =if(iferror(match(A208,'March 30 - M3 1006'!G:G,0),FALSE),"o","") | N208: =if(iferror(match(A208,'March 30 - M3 1006'!L:L,0),FALSE),"o","")
C209: =if(iferror(match(A209,'March 22 - RCH 301'!B:B,0),FALSE),"o","") | D209: =if(iferror(match(A209,'March 22 - RCH 301'!G:G,0),FALSE),"o","") | E209: =if(iferror(match(A209,'March 22 - RCH 301'!L:L,0),FALSE),"o","") | F209: =if(iferror(match(A209,'March 23 - M3 1006'!B:B,0),FALSE),"o","") | G209: =if(iferror(match(A209,'March 23 - M3 1006'!G:G,0),FALSE),"o","") | H209: =if(iferror(match(A209,'March 23 - M3 1006'!L:L,0),FALSE),"o","") | I209: =if(iferror(match(A209,'March 29 - M3 1006'!B:B,0),FALSE),"o","") | J209: =if(iferror(match(A209,'March 29 - M3 1006'!G:G,0),FALSE),"o","") | K209: =if(iferror(match(A209,'March 29 - M3 1006'!L:L,0),FALSE),"o","") | L209: =if(iferror(match(A209,'March 30 - M3 1006'!B:B,0),FALSE),"o","") | M209: =if(iferror(match(A209,'March 30 - M3 1006'!G:G,0),FALSE),"o","") | N209: =if(iferror(match(A209,'March 30 - M3 1006'!L:L,0),FALSE),"o","")
C210: =if(iferror(match(A210,'March 22 - RCH 301'!B:B,0),FALSE),"o","") | D210: =if(iferror(match(A210,'March 22 - RCH 301'!G:G,0),FALSE),"o","") | E210: =if(iferror(match(A210,'March 22 - RCH 301'!L:L,0),FALSE),"o","") | F210: =if(iferror(match(A210,'March 23 - M3 1006'!B:B,0),FALSE),"o","") | G210: =if(iferror(match(A210,'March 23 - M3 1006'!G:G,0),FALSE),"o","") | H210: =if(iferror(match(A210,'March 23 - M3 1006'!L:L,0),FALSE),"o","") | I210: =if(iferror(match(A210,'March 29 - M3 1006'!B:B,0),FALSE),"o","") | J210: =if(iferror(match(A210,'March 29 - M3 1006'!G:G,0),FALSE),"o","") | K210: =if(iferror(match(A210,'March 29 - M3 1006'!L:L,0),FALSE),"o","") | L210: =if(iferror(match(A210,'March 30 - M3 1006'!B:B,0),FALSE),"o","") | M210: =if(iferror(match(A210,'March 30 - M3 1006'!G:G,0),FALSE),"o","") | N210: =if(iferror(match(A210,'March 30 - M3 1006'!L:L,0),FALSE),"o","")
C211: =if(iferror(match(A211,'March 22 - RCH 301'!B:B,0),FALSE),"o","") | D211: =if(iferror(match(A211,'March 22 - RCH 301'!G:G,0),FALSE),"o","") | E211: =if(iferror(match(A211,'March 22 - RCH 301'!L:L,0),FALSE),"o","") | F211: =if(iferror(match(A211,'March 23 - M3 1006'!B:B,0),FALSE),"o","") | G211: =if(iferror(match(A211,'March 23 - M3 1006'!G:G,0),FALSE),"o","") | H211: =if(iferror(match(A211,'March 23 - M3 1006'!L:L,0),FALSE),"o","") | I211: =if(iferror(match(A211,'March 29 - M3 1006'!B:B,0),FALSE),"o","") | J211: =if(iferror(match(A211,'March 29 - M3 1006'!G:G,0),FALSE),"o","") | K211: =if(iferror(match(A211,'March 29 - M3 1006'!L:L,0),FALSE),"o","") | L211: =if(iferror(match(A211,'March 30 - M3 1006'!B:B,0),FALSE),"o","") | M211: =if(iferror(match(A211,'March 30 - M3 1006'!G:G,0),FALSE),"o","") | N211: =if(iferror(match(A211,'March 30 - M3 1006'!L:L,0),FALSE),"o","")
C212: =if(iferror(match(A212,'March 22 - RCH 301'!B:B,0),FALSE),"o","") | D212: =if(iferror(match(A212,'March 22 - RCH 301'!G:G,0),FALSE),"o","") | E212: =if(iferror(match(A212,'March 22 - RCH 301'!L:L,0),FALSE),"o","") | F212: =if(iferror(match(A212,'March 23 - M3 1006'!B:B,0),FALSE),"o","") | G212: =if(iferror(match(A212,'March 23 - M3 1006'!G:G,0),FALSE),"o","") | H212: =if(iferror(match(A212,'March 23 - M3 1006'!L:L,0),FALSE),"o","") | I212: =if(iferror(match(A212,'March 29 - M3 1006'!B:B,0),FALSE),"o","") | J212: =if(iferror(match(A212,'March 29 - M3 1006'!G:G,0),FALSE),"o","") | K212: =if(iferror(match(A212,'March 29 - M3 1006'!L:L,0),FALSE),"o","") | L212: =if(iferror(match(A212,'March 30 - M3 1006'!B:B,0),FALSE),"o","") | M212: =if(iferror(match(A212,'March 30 - M3 1006'!G:G,0),FALSE),"o","") | N212: =if(iferror(match(A212,'March 30 - M3 1006'!L:L,0),FALSE),"o","")
C213: =if(iferror(match(A213,'March 22 - RCH 301'!B:B,0),FALSE),"o","") | D213: =if(iferror(match(A213,'March 22 - RCH 301'!G:G,0),FALSE),"o","") | E213: =if(iferror(match(A213,'March 22 - RCH 301'!L:L,0),FALSE),"o","") | F213: =if(iferror(match(A213,'March 23 - M3 1006'!B:B,0),FALSE),"o","") | G213: =if(iferror(match(A213,'March 23 - M3 1006'!G:G,0),FALSE),"o","") | H213: =if(iferror(match(A213,'March 23 - M3 1006'!L:L,0),FALSE),"o","") | I213: =if(iferror(match(A213,'March 29 - M3 1006'!B:B,0),FALSE),"o","") | J213: =if(iferror(match(A213,'March 29 - M3 1006'!G:G,0),FALSE),"o","") | K213: =if(iferror(match(A213,'March 29 - M3 1006'!L:L,0),FALSE),"o","") | L213: =if(iferror(match(A213,'March 30 - M3 1006'!B:B,0),FALSE),"o","") | M213: =if(iferror(match(A213,'March 30 - M3 1006'!G:G,0),FALSE),"o","") | N213: =if(iferror(match(A213,'March 30 - M3 1006'!L:L,0),FALSE),"o","")
C214: =if(iferror(match(A214,'March 22 - RCH 301'!B:B,0),FALSE),"o","") | D214: =if(iferror(match(A214,'March 22 - RCH 301'!G:G,0),FALSE),"o","") | E214: =if(iferror(match(A214,'March 22 - RCH 301'!L:L,0),FALSE),"o","") | F214: =if(iferror(match(A214,'March 23 - M3 1006'!B:B,0),FALSE),"o","") | G214: =if(iferror(match(A214,'March 23 - M3 1006'!G:G,0),FALSE),"o","") | H214: =if(iferror(match(A214,'March 23 - M3 1006'!L:L,0),FALSE),"o","") | I214: =if(iferror(match(A214,'March 29 - M3 1006'!B:B,0),FALSE),"o","") | J214: =if(iferror(match(A214,'March 29 - M3 1006'!G:G,0),FALSE),"o","") | K214: =if(iferror(match(A214,'March 29 - M3 1006'!L:L,0),FALSE),"o","") | L214: =if(iferror(match(A214,'March 30 - M3 1006'!B:B,0),FALSE),"o","") | M214: =if(iferror(match(A214,'March 30 - M3 1006'!G:G,0),FALSE),"o","") | N214: =if(iferror(match(A214,'March 30 - M3 1006'!L:L,0),FALSE),"o","")
... C219: =if(iferror(match(A219,'March 22 - RCH 301'!B:B,0),FALSE),"o","") | D219: =if(iferror(match(A219,'March 22 - RCH 301'!G:G,0),FALSE),"o","") | E219: =if(iferror(match(A219,'March 22 - RCH 301'!L:L,0),FALSE),"o","") | F219: =if(iferror(match(A219,'March 23 - M3 1006'!B:B,0),FALSE),"o","") | G219: =if(iferror(match(A219,'March 23 - M3 1006'!G:G,0),FALSE),"o","") | H219: =if(iferror(match(A219,'March 23 - M3 1006'!L:L,0),FALSE),"o","") | I219: =if(iferror(match(A219,'March 29 - M3 1006'!B:B,0),FALSE),"o","") | J219: =if(iferror(match(A219,'March 29 - M3 1006'!G:G,0),FALSE),"o","") | K219: =if(iferror(match(A219,'March 29 - M3 1006'!L:L,0),FALSE),"o","") | L219: =if(iferror(match(A219,'March 30 - M3 1006'!B:B,0),FALSE),"o","") | M219: =if(iferror(match(A219,'March 30 - M3 1006'!G:G,0),FALSE),"o","") | N219: =if(iferror(match(A219,'March 30 - M3 1006'!L:L,0),FALSE),"o","")
